Workbook

Sheet Wyjaśnienia
A1: Budżet pierwszej edycji Nagrody Konstela
A2: Siedem osobnych budżetów, bo każdy sponsor finansuje nazwany zakres, a nie udział w całości. Akademia obejmuje pierwsze przejście oceny we wszystkich kategoriach.
A4: ILE I OD KOGO
A5: Zakładka | B5: Kto to finansuje | C5: Kwota netto
A6: Budżet Rozmowy z AI - nagrody, ocena i promocja | B6: Fundator puli nagród | C6: ='Budżet Rozmowy z AI'!$D$39 -> 547809.76
A7: Budżet Piosenki - plebiscyt na piosenkę | B7: Sponsor plebiscytu | C7: ='Budżet Piosenki'!$D$34 -> 265960
A8: Budżet Plakatu - plebiscyt na plakat | B8: Mecenas plebiscytu na plakat | C8: ='Budżet Plakatu'!$D$37 -> 176032
A9: Budżet Filmu - plebiscyt na film | B9: Sponsor plebiscytu filmu | C9: ='Budżet Filmu'!$D$39 -> 296776
A10: Budżet Akademii - pierwsza runda oceny we wszystkich kategoriach | B10: Sponsor Akademii (np. sieć handlowa - vouchery) | C10: ='Budżet Akademii'!$D$33 -> 160160
A11: Budżet Antologii - antologia i archiwum | B11: Partner wydawniczy / sponsor organizacyjny | C11: ='Budżet Antologii'!$D$39 -> 162162
A12: Budżet Gali - gala rozstrzygnięcia | B12: Sponsor gali | C12: ='Budżet Gali'!$D$26 -> 62048
A13: Budżet Uruchomienia - fundacja, znak, strona i narzędzia | B13: Mecenas Założycielski | C13: ='Budżet Uruchomienia'!$D$28 -> 183480
A14: RAZEM | C14: ='Budżet Rozmowy z AI'!$D$39+'Budżet Gali'!$D$26+'Budżet Antologii'!$D$39+'Budżet Uruchomienia'!$D$28+'Budżet Piosenki'!$D$34+'Budżet Plakatu'!$D$37+'Budżet Akademii'!$D$33+'Budżet Filmu'!$D$39 -> 1854427.8
A15: LICZBY, KTÓRE USTAWIASZ
A16: Zmieniasz wyłącznie żółte pola poniżej. Wszystkie budżety przeliczą się same.
A17: Stawka godzinowa organizatora (netto) | B17: 220 | C17: Podstawa wyceny Twojej pracy we wszystkich budżetach.
A18: Liczba zgłoszeń do Nagrody | B18: 150 | C18: Wpływa na godziny oceny formalnej i korespondencji.
A19: Nagroda główna (brutto) | B19: 300000 | C19: Największa pojedyncza pozycja całości.
A20: Wyróżnienie dla finalisty (brutto) | B20: 3000 | C20: Siedem osób z dziesiątki antologii, poza podium.
A21: Liczba wyróżnień | B21: 7 | C21: Dziesiątka minus laureat, drugie i trzecie miejsce.
A22: Nagroda za drugie miejsce (brutto) | B22: 40000 | C22: Druga rozmowa z werdyktu jury.
A23: Nagroda za trzecie miejsce (brutto) | B23: 10000 | C23: Trzecia rozmowa z werdyktu jury.
A24: Liczba zgłoszeń do plebiscytu | B24: 150 | C24: Wpływa na koszt kontroli zgłoszeń.
A25: Nagrody plebiscytu łącznie (brutto) | B25: 35000 | C25: 20 tys. + 10 tys. + 5 tys. dla czołowej trójki.
A26: Nagrody publiczności piosenki łącznie (brutto) | B26: 12000 | C26: 10 000 zł dla wykonawcy z największą liczbą głosów oraz 2 000 zł za najlepsze uzasadnienie oddanego głosu, wybierane przez trzyosobowy zespół spoza jury. Uzasadnienie jest obowiązkowe przy każdym głosie, od 200 do 1500 znaków (§ 11 ust. 2 regulaminu).
A27: Nagrody publiczności rozmowy łącznie (brutto) | B27: 12000 | C27: 10 000 zł dla rozmowy z największą liczbą głosów oraz 2 000 zł dla głosującego, który najlepiej uzasadnił swój głos. Nagroda Uczniowska 10 000 zł jest pozycją osobną.
A28: Nagranie studyjne - koszt za utwór (netto) | B28: 7500 | C28: Środek widełek 5-10 tys. Do wyceny przez Michała Sołtana.
... A35: Stawka VAT | B35: 0.23 | C35: Dotyczy faktur wystawianych sponsorom.
A36: Podatek od nagród (ryczałt)
A38: CZEGO JESZCZE NIE MA
A39: Honoraria jury we wszystkich plebiscytach - osobno za ocenę zgłoszeń i za etap przygotowania karty oceny
A40: Realizacja części artystycznej gali
A41: Po wpisaniu tych kwot rosną Budżet Piosenki, Budżet Plakatu i Budżet Filmu. W Budżecie Plakatu czekają na wycenę cztery pozycje, w Budżecie Filmu pięć - wszystkie opisane w kolumnie Uwagi.
A43: JAK CZYTAĆ BUDŻETY
A44: Każda z zakładek budżetowych ma ten sam układ: praca organizatora, koszty twarde, podsumowanie.
A45: W podsumowaniu jest kwota netto, VAT i kwota brutto, którą sponsor widzi na fakturze.
A46: Kolumna "Rok kosztu" w każdej zakładce mówi, na który rok edycji przypada dana pozycja: 2027 to rok naboru, 2028 to ocena jury, nagrody, produkcja antologii, gala i wystawy. Rezerwa i marża dzielą się proporcjonalnie do kosztów danego roku. Podział w tym układzie pokazuje załącznik "Zestawienie zadania".
A47: AKADEMIA - PARAMETRY SKALOWANIA
A48: Odczytów na jedno zgłoszenie w rundzie pierwszej | B48: 2 | C48: Regulamin § 8: co najmniej dwóch czytelników przy 21-60 zgłoszeniach; powyżej 200 przesiew jednoosobowy z drugim odczytem poniżej progu.
A49: Voucher za każde 100 ocenionych rozmów (netto) | B49: 500 | C49: Świadczenie rzeczowe sponsora Akademii. Do ustalenia ze sponsorem.
...

Sheet Budżet Rozmowy z AI
A1: Budżet Rozmowy z AI - nagrody, ocena i promocja
A2: Finansuje: Fundator nagród w plebiscycie na najlepszą rozmowę ze sztuczną inteligencją. Kwoty netto, chyba że napisano inaczej.
A3: Na żółto pola do edycji. Pozostałe liczą się same albo pochodzą z zakładki Wyjaśnienia.
A5: PRACA ORGANIZATORA
A6: Pozycja | B6: Godziny | C6: Minut na zgłoszenie | D6: Razem godzin | E6: Kwota | F6: Uwagi | G6: Rok kosztu
A7: Rekrutacja jury i Akademii, korespondencja | B7: 60 | C7: 0 | D7: =B7+C7*Wyjaśnienia!$B$18/60 -> 60 | E7: =D7*Wyjaśnienia!$B$17 -> 13200 | F7: 15 czytelników, 3-5 jurorów, lista rezerwowa | G7: 2027
A8: Próba kalibracyjna i dwie powtórki kotwic | B8: 24 | C8: 0 | D8: =B8+C8*Wyjaśnienia!$B$18/60 -> 24 | E8: =D8*Wyjaśnienia!$B$17 -> 5280 | F8: 3 rozmowy spoza edycji | G8: 2027
A9: Obsługa panelu oceny, przydziały, przypomnienia | B9: 50 | C9: 0 | D9: =B9+C9*Wyjaśnienia!$B$18/60 -> 50 | E9: =D9*Wyjaśnienia!$B$17 -> 11000 | F9: rozłożone na 12 miesięcy naboru | G9: 2027
A10: Archiwizacja i ocena formalna | B10: 8 | C10: 6 | D10: =B10+C10*Wyjaśnienia!$B$18/60 -> 23 | E10: =D10*Wyjaśnienia!$B$17 -> 5060 | F10: skrypt plus obsługa wyjątków | G10: 2027
A11: Korespondencja z uczestnikami | B11: 10 | C11: 4 | D11: =B11+C11*Wyjaśnienia!$B$18/60 -> 20 | E11: =D11*Wyjaśnienia!$B$17 -> 4400 | F11: potwierdzenia, kopie archiwalne, pytania | G11: 2027
A12: Postępowania szczególne | B12: 20 | C12: 0 | D12: =B12+C12*Wyjaśnienia!$B$18/60 -> 20 | E12: =D12*Wyjaśnienia!$B$17 -> 4400 | F12: inscenizacja, treści trudne, odmowy publikacji | G12: 2027
A13: Koordynacja rundy drugiej z jury | B13: 40 | C13: 0 | D13: =B13+C13*Wyjaśnienia!$B$18/60 -> 40 | E13: =D13*Wyjaśnienia!$B$17 -> 8800 | F13: spotkania, protokoły, rozbieżności | G13: 2028
A14: Rozmowy weryfikacyjne (10 finalistów) | B14: 25 | C14: 0 | D14: =B14+C14*Wyjaśnienia!$B$18/60 -> 25 | E14: =D14*Wyjaśnienia!$B$17 -> 5500 | F14: prowadzi Organizator osobiście | G14: 2028
A15: Rozliczenia, podatki, sprawozdanie dla sponsorów | B15: 25 | C15: 0 | D15: =B15+C15*Wyjaśnienia!$B$18/60 -> 25 | E15: =D15*Wyjaśnienia!$B$17 -> 5500 | F15: z księgowym | G15: 2028
A16: Komunikacja, media, strona | B16: 40 | C16: 0 | D16: =B16+C16*Wyjaśnienia!$B$18/60 -> 40 | E16: =D16*Wyjaśnienia!$B$17 -> 8800 | F16: przez cały rok | G16: 2027
A17: Razem praca | D17: =SUM(D7:D16) -> 327 | E17: =SUM(E7:E16) -> 71940
A19: KOSZTY TWARDE
A20: Pozycja | B20: Cena jednostkowa | C20: Ilość | D20: Kwota | E20: Uwagi | G20: Rok kosztu
A21: Medal laureata i dyplomy | B21: 1200 | C21: 1 | D21: =B21*C21 -> 1200 | E21: medal zwycięzcy, 10 dyplomów | G21: 2028
A22: Obsługa księgowa projektu | B22: 1500 | C22: 1 | D22: =B22*C22 -> 1500 | E22: ponad bieżącą obsługę działalności | G22: 2027
A23: Domeny konstela.org i konstela.pl | B23: 250 | C23: 1 | D23: =B23*C23 -> 250 | E23: opłacone | G23: 2027
A24: Honoraria jury | B24: 32000 | C24: 1 | D24: =B24*C24 -> 32000 | E24: 15 czytelników po 2 500 zł, 4 jurorów po 8 000 zł | F24: 4 jurorów po 8 000 zł; honoraria Akademii przeniesione do Budżetu Akademii | G24: 2028
A25: Honoraria jury za etap przygotowawczy: karta oceny i wagi kryteriów (netto) | B25: 0 | C25: 1 | D25: =B25*C25 -> 0 | E25: DO USTALENIA - etap przed naborem, osobny od oceny zgłoszeń; obejmuje opisy przedziałów punktowych i przykłady ich zastosowania Rok kosztu: 2027 - karta oceny powstaje przed otwarciem naboru. Jeżeli zapłata nastąpi później, pozycję trzeba przypisać do roku wypłaty. | G25: 2027
A26: Promocja naboru | B26: 15000 | C26: 1 | D26: =B26*C26 -> 15000 | E26: materiały, obsługa prasowa przy starcie i rozstrzygnięciu, płatne dotarcie | G26: 2027
A27: Nagrody publiczności (brutto) | B27: =Wyjaśnienia!$B$27 -> 12000 | C27: 1 | D27: =B27*C27 -> 12000 | E27: 10 000 zł dla zgłoszenia z największą liczbą głosów oraz 2 000 zł za najlepsze uzasadnienie oddanego głosu | G27: 2028
A28: Ubezpieczenie OC organizatora | B28: 0 | C28: 1 | D28: =B28*C28 -> 0 | E28: do ustalenia po konsultacji prawnej; na razie pokryte rezerwą | G28: 2027
A29: Nagroda Uczniowska (brutto) | B29: 10000 | C29: 1 | D29: =B29*C29 -> 10000 | E29: wskazywana przez grupy uczniowskie zgłaszane przez szkoły, jedna szkoła - jedno wskazanie; niezależna od werdyktu jury i od Nagrody Publiczności, może przypaść rozmowie spoza pierwszej dziesiątki | G29: 2028
A30: Infrastruktura i narzędzia AI na czas rozstrzygnięcia edycji, I-IV 2028 (4 mies.) | B30: 13333 | C30: 1 | D30: =B30*C30 -> 13333 | E30: hosting, magazyn kopii archiwalnych i licencje AI za cztery miesiące domykające edycję; roczne pozycje w Budżecie Uruchomienia kończą się w grudniu 2027, a gala wypada w kwietniu 2028
A31: Honoraria zespołu wybierającego najlepsze uzasadnienie głosu (netto) | B31: 3000 | C31: 1 | D31: =B31*C31 -> 3000 | E31: trzy osoby spoza jury, po 1 000 zł; czytają uzasadnienia oddanych głosów i wybierają nagrodzone (nagroda 2 000 zł mieści się w nagrodach publiczności)
A32: Razem koszty twarde | D32: =SUM(D21:D31) -> 88283
A34: PODSUMOWANIE
A35: Nagrody (brutto dla laureatów, bez VAT) | D35: =Wyjaśnienia!$B$19+Wyjaśnienia!$B$22+Wyjaśnienia!$B$23+Wyjaśnienia!$B$20*Wyjaśnienia!$B$21 -> 371000
A36: Praca organizatora | D36: =E17 -> 71940
A37: Koszty twarde | D37: =D32 -> 88283
A38: Rezerwa (od pracy i kosztów, bez nagród) | D38: =(D36+D37-D27-D29)*Wyjaśnienia!$B$32 -> 16586.76 | E38: liczona od pracy i kosztów twardych z wyłączeniem nagród publiczności i Nagrody Uczniowskiej - tak samo jak w pozostałych budżetach, gdzie rezerwa nagród nie obejmuje
A39: RAZEM NETTO | D39: =SUM(D35:D38) -> 547809.76
A40: VAT | D40: =D39*Wyjaśnienia!$B$35 -> 125996.24
A41: DO ZAPŁATY BRUTTO - ta liczba trafia na fakturę | D41: =D39+D40 -> 673806

Sheet Budżet Piosenki
A1: Budżet Piosenki - plebiscyt na piosenkę
A2: Finansuje: Fundator nagród w plebiscycie na piosenkę o sztucznej inteligencji. Kwoty netto, chyba że napisano inaczej.
A3: Na żółto pola do edycji. Pozostałe liczą się same albo pochodzą z zakładki Wyjaśnienia.
A5: PRACA ORGANIZATORA
A6: Pozycja | B6: Godziny | C6: Minut na zgłoszenie | D6: Razem godzin | E6: Kwota | F6: Uwagi | G6: Rok kosztu
A7: Kontrola formalna zgłoszeń plebiscytu | B7: 0 | C7: 10 | D7: =B7+C7*Wyjaśnienia!$B$24/60 -> 25 | E7: =D7*Wyjaśnienia!$B$17 -> 5500 | F7: 10 minut na zgłoszenie; przy dużych liczbach część kontroli automatyzowana. | G7: 2027
A8: Koordynacja nagrań studyjnych dziesięciu finalistów | B8: 40 | D8: =B8+C8*Wyjaśnienia!$B$24/60 -> 40 | E8: =D8*Wyjaśnienia!$B$17 -> 8800 | F8: umowy, terminy w studiu, przekazanie praw autorom | G8: 2028
A9: Obsługa jury plebiscytu: przydziały, obrady, werdykt | B9: 30 | D9: =B9+C9*Wyjaśnienia!$B$24/60 -> 30 | E9: =D9*Wyjaśnienia!$B$17 -> 6600 | F9: w tym preselekcja powyżej progu | G9: 2028
A10: Obsługa głosowania publiczności i ogłoszenie wyniku | B10: 20 | D10: =B10+C10*Wyjaśnienia!$B$24/60 -> 20 | E10: =D10*Wyjaśnienia!$B$17 -> 4400 | F10: bramka SMS, ukryte liczniki, ogłoszenie na gali | G10: 2028
A11: Komunikacja plebiscytu i dotarcie do wykonawców | B11: 50 | D11: =B11+C11*Wyjaśnienia!$B$24/60 -> 50 | E11: =D11*Wyjaśnienia!$B$17 -> 11000 | F11: grupy muzyków, szkoły muzyczne, scena coverowa, radia | G11: 2027
A12: Razem praca | D12: =SUM(D7:D11) -> 165 | E12: =SUM(E7:E11) -> 36300 | F12: Powyżej progu zgłoszeń pierwsze przejście oceny przechodzi na Akademię, tak jak w plebiscycie na rozmowę - dlatego te godziny nie rosną z naborem. Minuty na zgłoszenie dotyczą wyłącznie kontroli formalnej.
A14: KOSZTY TWARDE
A15: Pozycja | B15: Cena jednostkowa | C15: Ilość | D15: Kwota | E15: Uwagi | G15: Rok kosztu
A16: Nagrody plebiscytu (brutto dla laureatów) | B16: =Wyjaśnienia!$B$25 -> 35000 | C16: 1 | D16: =B16*C16 -> 35000 | E16: czołowa trójka; podatek 10% jak przy Nagrodzie | G16: 2028
A17: Nagrody publiczności (brutto) | B17: =Wyjaśnienia!$B$26 -> 12000 | C17: 1 | D17: =B17*C17 -> 12000 | E17: 10 000 zł dla zgłoszenia z największą liczbą głosów oraz 2 000 zł za najlepsze uzasadnienie oddanego głosu | G17: 2028
A18: Nagrania studyjne dziesięciu finalistów (netto) | B18: =Wyjaśnienia!$B$28 -> 7500 | C18: =Wyjaśnienia!$B$29 -> 10 | D18: =B18*C18 -> 75000 | E18: prawa do nagrań przechodzą na autorów | G18: 2028
A19: Hymn z teledyskiem (netto) | B19: =Wyjaśnienia!$B$30 -> 80000 | C19: 1 | D19: =B19*C19 -> 80000 | E19: premiera w czasie trwania naboru w 2027; otwarcie edycji nie jest od niej uzależnione | G19: 2027
A20: Medal zwycięzcy i dyplomy finalistów (netto) | B20: =Wyjaśnienia!$B$31 -> 1200 | C20: 1 | D20: =B20*C20 -> 1200 | E20: ten sam medal, który otrzymuje laureat plebiscytu rozmów; dyplomy dla całej dziesiątki | G20: 2028
A21: Honoraria jury plebiscytu za ocenę (netto) | B21: 0 | C21: 1 | D21: =B21*C21 -> 0 | E21: DO USTALENIA - kotwica: stawka jury ok. 290 zł/h, ok. 15 h na jurora | G21: 2028
A22: Honoraria jury za etap przygotowawczy: karta oceny i wagi kryteriów (netto) | B22: 0 | C22: 1 | D22: =B22*C22 -> 0 | E22: DO USTALENIA - etap przed naborem, osobny od oceny zgłoszeń; kotwica: stawka jury ok. 290 zł/h | G22: 2027
A23: Realizacja części artystycznej gali (netto) | B23: 0 | C23: 1 | D23: =B23*C23 -> 0 | E23: DO WYCENY - zależy od miejsca gali, które nie jest wybrane | G23: 2028
A24: Obsługa prawna plebiscytu (netto) | B24: 0 | C24: 1 | D24: =B24*C24 -> 0 | E24: DO WYCENY - zakres plebiscytowy nie był objęty wyceną z 22.10.2026; osobne zlecenie | F24: odrębne zlecenie na pytania plebiscytowe; kwota z zapasem wobec ofert kancelarii | G24: 2027
A25: Dojazd i nocleg dziesięciu finalistów na galę - w Budżecie Gali (netto) | B25: 0 | C25: 1 | D25: =B25*C25 -> 0 | E25: pokrywa je sponsor gali; pozycja zostaje w zestawieniu, żeby było widać, że koszt istnieje i kto go ponosi | G25: 2028
A26: Honoraria zespołu wybierającego najlepsze uzasadnienie głosu (netto) | B26: 3000 | C26: 1 | D26: =B26*C26 -> 3000 | E26: trzy osoby spoza jury, po 1 000 zł; czytają uzasadnienia oddanych głosów i wybierają nagrodzone (nagroda 2 000 zł mieści się w nagrodach publiczności)
A27: Razem koszty twarde | D27: =SUM(D16:D26) -> 206200
A29: PODSUMOWANIE
A30: Nagrody (brutto dla laureatów, bez VAT) | D30: =Wyjaśnienia!$B$25+Wyjaśnienia!$B$26 -> 47000
A31: Praca organizatora | D31: =E12 -> 36300
A32: Koszty twarde bez nagród | D32: =D27-D30 -> 159200
A33: Rezerwa (od pracy i kosztów, bez nagród) | D33: =(D31+D32)*Wyjaśnienia!$B$34 -> 23460
A34: RAZEM NETTO | D34: =SUM(D30:D33) -> 265960
A35: VAT | D35: =D34*Wyjaśnienia!$B$35 -> 61170.8
A36: DO ZAPŁATY BRUTTO - ta liczba trafia na fakturę | D36: =D34+D35 -> 327130.8

Sheet Budżet Plakatu
A1: Budżet Plakatu - plebiscyt na plakat
A2: Finansuje: Mecenas plebiscytu na plakat. Kwoty netto, chyba że napisano inaczej.
A3: Na żółto pola do edycji. Pozostałe liczą się same albo pochodzą z zakładki Wyjaśnienia.
A5: PRACA ORGANIZATORA
A6: Pozycja | B6: Godziny | C6: Minut na zgłoszenie | D6: Razem godzin | E6: Kwota | F6: Uwagi | G6: Rok kosztu
A7: Kontrola formalna zgłoszeń plakatów | B7: 0 | C7: 10 | D7: =B7+C7*Wyjaśnienia!$B$55/60 -> 25 | E7: =D7*Wyjaśnienia!$B$17 -> 5500 | F7: format, proporcje, rozdzielczość, oświadczenia; 10 minut na zgłoszenie, w tym obejrzenie nagrania z pracy trwającego co najmniej 3 minuty | G7: 2027
A8: Obsługa jury plakatu: przydziały, preselekcja, obrady, werdykt | B8: 30 | D8: =B8+C8*Wyjaśnienia!$B$55/60 -> 30 | E8: =D8*Wyjaśnienia!$B$17 -> 6600 | F8: werdykt zapada przed galą, bo okładka antologii idzie do druku | G8: 2028
A9: Obsługa głosowania publiczności i ogłoszenie wyniku | B9: 20 | D9: =B9+C9*Wyjaśnienia!$B$55/60 -> 20 | E9: =D9*Wyjaśnienia!$B$17 -> 4400 | F9: ukryte liczniki, ogłoszenie na gali | G9: 2028
A10: Przyjęcie, ewidencja i zwrot oryginałów finalistów | B10: 35 | D10: =B10+C10*Wyjaśnienia!$B$55/60 -> 35 | E10: =D10*Wyjaśnienia!$B$17 -> 7700 | F10: Dwie lokalizacje: wystawa przy gali i wernisaż w galerii sztuki (regulamin § 10 ust. 3a), więc protokoły, przewóz między miejscami i ubezpieczenie na dłuższy okres - do 120 dni od dostarczenia pracy. Przy wycenie sprawdzić, czy 35 godzin wystarcza. | G10: 2028
A11: Uzgodnienie okładki antologii ze zwycięzcą | B11: 15 | D11: =B11+C11*Wyjaśnienia!$B$55/60 -> 15 | E11: =D11*Wyjaśnienia!$B$17 -> 3300 | F11: zgoda w 7 dni po werdykcie, typografia, kadrowanie, redakcja | G11: 2028
A12: Dotarcie do szkół artystycznych i środowiska ilustratorów | B12: 50 | D12: =B12+C12*Wyjaśnienia!$B$55/60 -> 50 | E12: =D12*Wyjaśnienia!$B$17 -> 11000 | F12: ASP, licea plastyczne, grupy ilustratorów, konkursy plakatowe | G12: 2027
A13: Obsługa licytacji: warunki, zgody, rozliczenia | B13: 20 | D13: =B13+C13*Wyjaśnienia!$B$55/60 -> 20 | E13: =D13*Wyjaśnienia!$B$17 -> 4400 | F13: propozycja po zamknięciu ocen, podział 50/50, rozliczenie na piśmie. Licytacja towarzyszy wystawie w galerii, dlatego w zestawieniu zadania te godziny są wykazane poza zakresem pytania do MKiDN. | G13: 2028
A14: Razem praca | D14: =SUM(D7:D13) -> 195 | E14: =SUM(E7:E13) -> 42900 | F14: Powyżej progu zgłoszeń pierwsze przejście oceny przechodzi na Akademię, tak jak w plebiscycie na rozmowę - dlatego te godziny nie rosną z naborem. Minuty na zgłoszenie dotyczą wyłącznie kontroli formalnej.
A16: KOSZTY TWARDE
A17: Pozycja | B17: Cena jednostkowa | C17: Ilość | D17: Kwota | E17: Uwagi | G17: Rok kosztu
A18: Nagrody plakatu (brutto dla laureatów) | B18: =Wyjaśnienia!$B$56 -> 90000 | C18: 1 | D18: =B18*C18 -> 90000 | E18: czołowa trójka: 50, 25 i 15 tys.; podatek 10% jak przy Nagrodzie | G18: 2028
A19: Nagrody publiczności (brutto) | B19: =Wyjaśnienia!$B$57 -> 12000 | C19: 1 | D19: =B19*C19 -> 12000 | E19: 10 000 zł dla zgłoszenia z największą liczbą głosów oraz 2 000 zł za najlepsze uzasadnienie oddanego głosu | G19: 2028
A20: Medal zwycięzcy i dyplomy finalistów (netto) | B20: =Wyjaśnienia!$B$58 -> 1200 | C20: 1 | D20: =B20*C20 -> 1200 | E20: ten sam medal, który otrzymuje laureat plebiscytu rozmów; dyplomy dla całej dziesiątki | G20: 2028
A21: Honoraria jury plakatu za ocenę (netto) | B21: 0 | C21: 1 | D21: =B21*C21 -> 0 | E21: DO USTALENIA - stawka godzinowa jest przy nazwisku złym narzędziem; kotwica z Wyjaśnień (5 osób x 10 h x 290 zł) dałaby 14 500 zł | G21: 2028
A22: Honoraria jury za etap przygotowawczy: karta oceny i wagi kryteriów (netto) | B22: 0 | C22: 1 | D22: =B22*C22 -> 0 | E22: DO USTALENIA - etap przed naborem, osobny od oceny zgłoszeń; obejmuje opisy przedziałów punktowych i przykłady ich zastosowania | G22: 2027
A23: Transport oryginałów w obie strony (netto) | B23: =Wyjaśnienia!$B$63*2 -> 800 | C23: =Wyjaśnienia!$B$62 -> 10 | D23: =B23*C23 -> 8000 | E23: szacunek, nie oferta; organizator pokrywa obie strony | G23: 2028
A24: Ubezpieczenie prac na czas wystawy (netto) | B24: =Wyjaśnienia!$B$64 -> 3000 | C24: 1 | D24: =B24*C24 -> 3000 | E24: szacunek przy sumie deklarowanej rzędu 100 tys. zł | G24: 2028
A25: Wystawa prac finałowych w postaci gwarantowanej (netto) | B25: 8000 | C25: 1 | D25: =B25*C25 -> 8000 | E25: postać minimalna zagwarantowana w umowie z mecenasem: dziesięć prac, opisy i nazwisko mecenasa, miejsce publicznie dostępne, co najmniej 14 dni; przy gali albo w osobnym terminie do trzech miesięcy po ogłoszeniu wyników. Bogatsza oprawa - zawieszenie, oświetlenie sceniczne, wernisaż - pozostaje do wyceny i do osobnego aneksu | G25: 2028
A26: Obsługa prawna regulaminu plakatu (netto) | B26: 0 | C26: 1 | D26: =B26*C26 -> 0 | E26: DO WYCENY - odrębne zlecenie kancelarii, nie złożone | G26: 2027
A27: Dojazd i nocleg finalistów na galę - w Budżecie Gali (netto) | B27: 0 | C27: 1 | D27: =B27*C27 -> 0 | E27: pokrywa je sponsor gali; pozycja zostaje w zestawieniu, żeby było widać, że koszt istnieje i kto go ponosi | G27: 2028
A28: Polisa: wycena prac, rozszerzenie na przechowywanie i okres po sprzedaży (netto) | B28: 0 | C28: 1 | D28: =B28*C28 -> 0 | E28: DO WYCENY - polisa ma objąć cały uzgodniony okres: transport w obie strony, przechowywanie u organizatora, obie wystawy oraz czas po sprzedaży do wydania pracy nabywcy; do ustalenia suma ubezpieczenia na pracę, udział własny i procedura zgłoszenia szkody | G28: 2028
A29: Honoraria zespołu wybierającego najlepsze uzasadnienie głosu (netto) | B29: 3000 | C29: 1 | D29: =B29*C29 -> 3000 | E29: trzy osoby spoza jury, po 1 000 zł; czytają uzasadnienia oddanych głosów i wybierają nagrodzone (nagroda 2 000 zł mieści się w nagrodach publiczności)
A30: Razem koszty twarde | D30: =SUM(D18:D29) -> 125200
A32: PODSUMOWANIE
A33: Nagrody (brutto dla laureatów, bez VAT) | D33: =Wyjaśnienia!$B$56+Wyjaśnienia!$B$57 -> 102000
A34: Praca organizatora | D34: =E14 -> 42900
A35: Koszty twarde bez nagród | D35: =D30-D33 -> 23200
A36: Rezerwa (od pracy i kosztów, bez nagród) | D36: =(D34+D35)*Wyjaśnienia!$B$65 -> 7932
A37: RAZEM NETTO | D37: =SUM(D33:D36) -> 176032
A38: VAT | D38: =D37*Wyjaśnienia!$B$35 -> 40487.36
A39: DO ZAPŁATY BRUTTO - ta liczba trafia na fakturę | D39: =D37+D38 -> 216519.36
A41: POZA ZAKRESEM PYTANIA DO MKiDN
A42: Wystawa w galerii sztuki jest celem, nie zobowiązaniem regulaminowym, i ma własne źródło finansowania. Pierwsza pozycja poniżej nie wchodzi do sum powyżej, bo czeka na wycenę. Druga powtarza godziny już policzone w wierszu 13 i również nie jest do sum dodawana - pokazuje tylko, ile z pracy organizatora przypada na część poza pytaniem do MKiDN.
A43: Pozycja | B43: Cena jednostkowa | C43: Ilość | D43: Kwota | E43: Uwagi | G43: Rok kosztu
A44: Realizacja wernisażu i wystawy w galerii sztuki (netto) | B44: 0 | C44: 1 | D44: =B44*C44 -> 0 | E44: DO WYCENY - zawieszenie, oświetlenie, opisy prac, obsługa wernisażu i przewóz między miejscami. Finansuje partner galerii.
...

Sheet Budżet Filmu
A1: Budżet Filmu - plebiscyt na film
A2: Finansuje: Fundator nagród w plebiscycie na film o sztucznej inteligencji. Kwoty netto, chyba że napisano inaczej.
A3: Na żółto pola do edycji w zakładce Wyjaśnienia. Pierwsze przejście oceny prowadzi Akademia filmu i jej koszt stoi w zakładce Budżet Akademii, żeby nie liczyć go dwa razy.
A5: PRACA ORGANIZATORA
A6: Pozycja | B6: Godziny | C6: Minut na zgłoszenie | D6: Razem godzin | E6: Kwota | F6: Uwagi | G6: Rok kosztu
A7: Kontrola formalna zgłoszeń filmów | B7: 0 | C7: 12 | D7: =B7+C7*Wyjaśnienia!$B$68/60 -> 30 | E7: =D7*Wyjaśnienia!$B$17 -> 6600 | F7: czas trwania, język, data ukończenia, działający odnośnik, miniatura, deklaracja, oświadczenia; 12 minut na zgłoszenie | G7: 2027
A8: Weryfikacja historii zgłoszonego filmu | B8: 5 | C8: 8 | D8: =B8+C8*Wyjaśnienia!$B$68/60 -> 25 | E8: =D8*Wyjaśnienia!$B$17 -> 5500 | F8: regulamin § 3a: film powstaje na potrzeby plebiscytu, więc sprawdzamy datę publikacji i publicznie dostępne wyniki konkursów | G8: 2027
A9: Obsługa Akademii filmu i jury: przydziały, karty, obrady, werdykt | B9: 60 | D9: =B9+C9*Wyjaśnienia!$B$68/60 -> 60 | E9: =D9*Wyjaśnienia!$B$17 -> 13200 | F9: dwa przejścia oceny, dziesięciu finalistów, kolejność całej dziesiątki | G9: 2028
A10: Obsługa głosowania publiczności i ogłoszenie wyniku | B10: 20 | D10: =B10+C10*Wyjaśnienia!$B$68/60 -> 20 | E10: =D10*Wyjaśnienia!$B$17 -> 4400 | F10: ukryte liczniki, ogłoszenie na gali | G10: 2028
A11: Zebranie zwiastunów piątki i przygotowanie bloku galowego | B11: 40 | D11: =B11+C11*Wyjaśnienia!$B$68/60 -> 40 | E11: =D11*Wyjaśnienia!$B$17 -> 8800 | F11: zwiastun jest częścią zgłoszenia i po zamknięciu naboru nie podlega zmianie; organizator zbiera zwiastuny piątki, sprawdza format i układa kolejność bloku galowego | G11: 2028
A12: Złożenie zestawu dziesiątki i rozmowy z dystrybutorami | B12: 40 | D12: =B12+C12*Wyjaśnienia!$B$68/60 -> 40 | E12: =D12*Wyjaśnienia!$B$17 -> 8800 | F12: regulamin § 10 ust. 4: termin i miejsce ogłaszane najpóźniej w dniu gali, udział za zgodą autora | G12: 2028
A13: Prowadzenie Projektorni i archiwum filmów | B13: 25 | D13: =B13+C13*Wyjaśnienia!$B$68/60 -> 25 | E13: =D13*Wyjaśnienia!$B$17 -> 5500 | F13: wpisy po ocenie formalnej, oznaczanie odnośników, które przestały działać | G13: 2027
A14: Dotarcie do szkół filmowych, kół filmowych i festiwali | B14: 50 | D14: =B14+C14*Wyjaśnienia!$B$68/60 -> 50 | E14: =D14*Wyjaśnienia!$B$17 -> 11000 | F14: PWSFTviT, wydziały filmowe, festiwale krótkiego metrażu, domy kultury | G14: 2027
A15: Pobranie, opis i sprawdzenie kopii archiwalnych filmów | B15: 20 | C15: 3 | D15: =B15+C15*Wyjaśnienia!$B$68/60 -> 27.5 | E15: =D15*Wyjaśnienia!$B$17 -> 6050 | F15: regulamin § 12 ust. 2 lit. a: kopia archiwalna nieudostępniana publicznie, pobierana po zamknięciu naboru; 20 godzin na metodę, opis i kontrolę kompletności oraz 3 minuty na zgłoszenie | G15: 2028
A16: Razem praca | D16: =SUM(D7:D15) -> 317.5 | E16: =SUM(E7:E15) -> 69850 | F16: Minuty na zgłoszenie dotyczą wyłącznie kontroli formalnej. Godziny obsługi oceny nie rosną wprost z naborem, bo pierwsze przejście wykonuje Akademia filmu - jej koszt rośnie i stoi w Budżecie Akademii.
A18: KOSZTY TWARDE
A19: Pozycja | B19: Cena jednostkowa | C19: Ilość | D19: Kwota | E19: Uwagi | G19: Rok kosztu
A20: Nagrody filmu (brutto dla laureatów) | B20: =Wyjaśnienia!$B$69 -> 180000 | C20: 1 | D20: =B20*C20 -> 180000 | E20: czołowa trójka: 100, 50 i 30 tys.; siedem wyróżnień bez nagrody pieniężnej; podatek 10% jak przy Nagrodzie | G20: 2028
A21: Nagrody publiczności (brutto) | B21: =Wyjaśnienia!$B$70 -> 12000 | C21: 1 | D21: =B21*C21 -> 12000 | E21: 10 000 zł dla zgłoszenia z największą liczbą głosów oraz 2 000 zł za najlepsze uzasadnienie oddanego głosu | G21: 2028
A22: Medal zwycięzcy i dyplomy finalistów (netto) | B22: =Wyjaśnienia!$B$71 -> 1200 | C22: 1 | D22: =B22*C22 -> 1200 | E22: ten sam medal, który otrzymują zwycięzcy pozostałych plebiscytów; dyplomy dla dziesięciu finalistów | G22: 2028
A23: Honoraria jury filmu za ocenę (netto) | B23: 0 | C23: 1 | D23: =B23*C23 -> 0 | E23: DO USTALENIA - kotwica z Wyjaśnień (5 osób x 40 h x 290 zł) dałaby 58 000 zł; 40 h to 30 h oglądania dwudziestu filmów przekazanych jury plus karty, obrady i werdykt | G23: 2028
A24: Honoraria jury za etap przygotowawczy: karta oceny i wagi kryteriów (netto) | B24: 0 | C24: 1 | D24: =B24*C24 -> 0 | E24: DO USTALENIA - etap przed naborem, osobny od oceny zgłoszeń; obejmuje opisy przedziałów punktowych i przykłady ich zastosowania | G24: 2027
A25: Przygotowanie techniczne zwiastunów do emisji galowej (netto) | B25: 0 | C25: 1 | D25: =B25*C25 -> 0 | E25: DO WYCENY - pobranie pięciu zwiastunów w jakości emisyjnej, zgodność formatów, normalizacja dźwięku, plansze z tytułami; zwiastun dostarcza autor, Organizator nie montuje fragmentów filmów | G25: 2028
A26: Pokaz kuratorski filmów finałowych w postaci gwarantowanej (netto) | B26: 12000 | C26: 1 | D26: =B26*C26 -> 12000 | E26: postać minimalna zagwarantowana w umowie z fundatorem: jeden seans blokowy z wyboru filmów finałowych w kinie studyjnym albo instytucji kultury, wstęp wolny, w ciągu trzech miesięcy po gali, ze spotkaniem z twórcami. Obejmuje salę i obsługę techniczną, przygotowanie kopii i materiały informacyjne, przejazdy i noclegi twórców prezentowanych filmów oraz honorarium prowadzącego. Szersza dystrybucja kinowa i emisja w serwisie streamingowym pozostają celem, zależnym od pozyskania partnera, i nie są tu wycenione | G26: 2028
A27: Dojazd i nocleg finalistów na galę - w Budżecie Gali (netto) | B27: 0 | C27: 1 | D27: =B27*C27 -> 0 | E27: pokrywa je sponsor gali; pozycja zostaje w zestawieniu, żeby było widać, że koszt istnieje i kto go ponosi | G27: 2028
A28: Obsługa prawna regulaminu filmu (netto) | B28: 0 | C28: 1 | D28: =B28*C28 -> 0 | E28: DO WYCENY - odrębne zlecenie kancelarii, nie złożone; siedem miejsc wypisanych na końcu regulaminu, w tym status filmu wygenerowanego w całości | G28: 2027
A29: Honoraria zespołu wybierającego najlepsze uzasadnienie głosu (netto) | B29: 3000 | C29: 1 | D29: =B29*C29 -> 3000 | E29: trzy osoby spoza jury, po 1 000 zł; czytają uzasadnienia oddanych głosów i wybierają nagrodzone (nagroda 2 000 zł mieści się w nagrodach publiczności)
A30: Magazyn kopii archiwalnych filmów: 5 lat retencji (netto, za rok) | B30: 1500 | C30: 5 | D30: =B30*C30 -> 7500 | E30: magazyn obiektowy w UE z kopią zapasową, bez publicznego odtwarzania: rzędu 400-600 GB w jednej kopii, dwa razy tyle z zapasową. Pięć lat retencji opłacone z góry, bo tyle trwa obietnica wobec Fundatora i wobec autorów; o dalszym przechowywaniu rozstrzyga Rada Fundacji | G30: 2028
A31: Razem koszty twarde | D31: =SUM(D20:D30) -> 215700
A33: PODSUMOWANIE
A34: Nagrody (brutto dla laureatów, bez VAT) | D34: =Wyjaśnienia!$B$69+Wyjaśnienia!$B$70 -> 192000
A35: Praca organizatora | D35: =Wyjaśnienia!$B$69+Wyjaśnienia!$B$70 -> 192000
A36: Koszty twarde bez nagród | D36: =E16 -> 69850
A37: Rezerwa (od pracy i kosztów, bez nagród) | D37: =D31-D35 -> 23700
A38: RAZEM NETTO | D38: =(D36+D37)*Wyjaśnienia!$B$76 -> 11226
A39: VAT | D39: =SUM(D35:D38) -> 296776
A40: DO ZAPŁATY BRUTTO - ta liczba trafia na fakturę | D40: =D39*Wyjaśnienia!$B$35 -> 68258.48
D41: =D39+D40 -> 365034.48

Sheet Budżet Akademii
A1: Budżet Akademii - pierwsza runda oceny we wszystkich kategoriach
A2: Finansuje: Sponsor Akademii. Kwoty netto. Vouchery są świadczeniem rzeczowym i rosną wprost z liczbą ocenionych rozmów.
A3: Na żółto pola do edycji w zakładce Wyjaśnienia. Praca organizatora przy prowadzeniu Akademii została w budżetach poszczególnych plebiscytów, żeby nie liczyć jej dwa razy.
A5: ILE PRACY TRZEBA WYKONAĆ
A6: Pozycja | B6: Liczba | F6: Uwagi
A7: Zgłoszenia rozmów do Nagrody | B7: =Wyjaśnienia!$B$18 -> 150 | F7: Honorarium obejmuje także oznaczanie zastrzeżeń prawnych przy czytaniu (regulamin § 8 ust. 3a): dane osób trzecich, całe cudze utwory krótkie, wgrane cudze materiały. Oznaczenie nie wpływa na punktację.
A8: Odczytów na jedno zgłoszenie rozmowy | B8: =Wyjaśnienia!$B$48 -> 2 | F8: regulamin § 8
A9: Razem odczytów rozmów | B9: =B7*B8 -> 300 | F9: to jest praca, którą finansuje sponsor Akademii
A10: Zgłoszenia filmów do plebiscytu | B10: =Wyjaśnienia!$B$68 -> 150 | F10: Akademia filmu działa od pierwszej edycji, a nie po przekroczeniu progu: film trwa do 90 minut, więc pierwszego przejścia nie da się zrobić kilkuosobowym jury (regulamin filmu § 8 ust. 4).
A11: Obejrzeń jednego filmu | B11: =Wyjaśnienia!$B$77 -> 2 | F11: dwa niezależne obejrzenia, jak dwa odczyty rozmowy
A12: Razem obejrzeń filmów | B12: =B10*B11 -> 300 | F12: każde obejrzenie to film do 90 minut plus karta oceny, czyli około 2 godzin
A14: WYNAGRODZENIE OCENIAJĄCYCH
A15: Pozycja | B15: Stawka | C15: Ilość | D15: Kwota | F15: Uwagi | G15: Rok kosztu
A16: Honorarium podstawowe czytelników rozmów | B16: =Wyjaśnienia!$B$50 -> 2500 | C16: =Wyjaśnienia!$B$51 -> 15 | D16: =B16*C16 -> 37500 | F16: przeniesione z Budżetu Rozmowy z AI | G16: 2027
A17: Vouchery za oceniane rozmowy | B17: =Wyjaśnienia!$B$49 -> 500 | C17: =ROUNDUP(B9/100,0) -> 3 | D17: =B17*C17 -> 1500 | F17: jeden voucher za każde rozpoczęte 100 odczytów | G17: 2027
A18: Honorarium oceniających filmy, za jedno obejrzenie | B18: =Wyjaśnienia!$B$78 -> 300 | C18: =B12 -> 300 | D18: =B18*C18 -> 90000 | F18: 300 zł za obejrzenie z wypełnieniem karty oceny, czyli około 150 zł za godzinę. Ustalenie z 26.10.2026; kwota rośnie wprost z liczbą zgłoszonych filmów. | G18: 2028
A19: Razem dla oceniających | D19: =SUM(D16:D18) -> 129000
A21: KOSZTY TWARDE
A22: Pozycja | B22: Cena jednostkowa | C22: Ilość | D22: Kwota | F22: Uwagi | G22: Rok kosztu
A23: Obsługa i rozliczenie voucherów | B23: 2000 | C23: 1 | D23: =B23*C23 -> 2000 | F23: ewidencja, PIT-11 dla czytelników, korespondencja | G23: 2027
A24: Materiały kalibracyjne i szkolenie czytelników rozmów | B24: 3000 | C24: 1 | D24: =B24*C24 -> 3000 | F24: trzy rozmowy kotwiczne, instrukcja, spotkanie wprowadzające | G24: 2027
A25: Materiały kalibracyjne i szkolenie oceniających filmy | B25: 5000 | C25: 1 | D25: =B25*C25 -> 5000 | F25: trzy filmy kotwiczne z rozpisaną punktacją, instrukcja oznaczania zastrzeżeń i spotkanie wprowadzające; droższe niż przy rozmowach, bo materiał kotwiczny trzeba obejrzeć, a nie przeczytać | G25: 2027
A26: Panel oceniających: hosting, konta, obsługa odnośników | B26: 4000 | C26: 1 | D26: =B26*C26 -> 4000 | F26: filmów nie trzymamy u siebie, ale panel musi je kolejkować, odtwarzać z kanału autora i wyłapywać odnośniki, które przestały działać | G26: 2027
A27: Razem koszty twarde | D27: =SUM(D23:D26) -> 14000
A29: PODSUMOWANIE
A30: Wynagrodzenie oceniających | D30: =D19 -> 129000
A31: Koszty twarde | D31: =D27 -> 14000
A32: Rezerwa | D32: =(D30+D31)*Wyjaśnienia!$B$32 -> 17160
A33: RAZEM NETTO | D33: =SUM(D30:D32) -> 160160
A34: VAT | D34: =D33*Wyjaśnienia!$B$35 -> 36836.8
A35: DO ZAPŁATY BRUTTO - ta liczba trafia na fakturę | D35: =D33+D34 -> 196996.8
A37: JAK TO SIĘ SKALUJE
A38: Vouchery i honoraria za obejrzenia rosną wprost z liczbą zgłoszeń, więc sponsor płaci za wykonaną pracę, a nie za prognozę. Kolumna godzin liczy pracę akademii od liczby ODCZYTÓW, po przyjętym czasie jednego odczytu z zakładki Wyjaśnienia; ilu osób to wymaga, zależy od tego, ile godzin daje pojedynczy czytelnik, i tego tabela nie przesądza. Przy większych wolumenach nie modeluje też odrębnie trybu jednoosobowego, drugich odczytów poniżej progu ani audytu losowego - te trzy rzeczy trzeba policzyć osobno przed ogłoszeniem progu.
A39: Zgłoszeń w edycji | B39: Odczytów rozmów | C39: Voucherów | D39: Koszt voucherów | E39: Godzin pracy akademii
A40: 150 | B40: =A40*Wyjaśnienia!$B$48 -> 300 | C40: =ROUNDUP(B40/100,0) -> 3 | D40: =C40*Wyjaśnienia!$B$49 -> 1500 | E40: =ROUNDUP(B40*Wyjaśnienia!$B$52/60,0) -> 150
A41: 1000 | B41: =A41*Wyjaśnienia!$B$48 -> 2000 | C41: =ROUNDUP(B41/100,0) -> 20 | D41: =C41*Wyjaśnienia!$B$49 -> 10000 | E41: =ROUNDUP(B41*Wyjaśnienia!$B$52/60,0) -> 1000
A42: 10000 | B42: =A42*Wyjaśnienia!$B$48 -> 20000 | C42: =ROUNDUP(B42/100,0) -> 200 | D42: =C42*Wyjaśnienia!$B$49 -> 100000 | E42: =ROUNDUP(B42*Wyjaśnienia!$B$52/60,0) -> 10000
A43: 100000 | B43: =A43*Wyjaśnienia!$B$48 -> 200000 | C43: =ROUNDUP(B43/100,0) -> 2000 | D43: =C43*Wyjaśnienia!$B$49 -> 1000000 | E43: =ROUNDUP(B43*Wyjaśnienia!$B$52/60,0) -> 100000
A44: 1000000 | B44: =A44*Wyjaśnienia!$B$48 -> 2000000 | C44: =ROUNDUP(B44/100,0) -> 20000 | D44: =C44*Wyjaśnienia!$B$49 -> 10000000 | E44: =ROUNDUP(B44*Wyjaśnienia!$B$52/60,0) -> 1000000
A46: Filmów w edycji | B46: Obejrzeń | C46: Honoraria za obejrzenia | D46: Godzin oglądania | E46: Potrzebnych oceniających
...

Sheet Budżet Antologii
A1: Budżet Antologii - antologia i archiwum
A2: Finansuje: Partner wydawniczy / sponsor organizacyjny. Kwoty netto, chyba że napisano inaczej.
A3: Na żółto pola do edycji. Pozostałe liczą się same albo pochodzą z zakładki Wyjaśnienia.
A5: PRACA ORGANIZATORA
A6: Pozycja | B6: Godziny | C6: Minut na zgłoszenie | D6: Razem godzin | E6: Kwota | F6: Uwagi | G6: Rok kosztu
A7: Antologia: redakcja not jury i uzupełnienia | B7: 45 | C7: 0 | D7: =B7+C7*Wyjaśnienia!$B$18/60 -> 45 | E7: =D7*Wyjaśnienia!$B$17 -> 9900 | F7: noty pisze jury (§ 8 ust. 13a) | G7: 2028
A8: Skład, korekta autorska, EPUB i PDF | B8: 40 | C8: 0 | D8: =B8+C8*Wyjaśnienia!$B$18/60 -> 40 | E8: =D8*Wyjaśnienia!$B$17 -> 8800 | F8: szablon przygotowany w styczniu | G8: 2028
A9: Rozstrzyganie zgłoszeń oznaczonych przez oceniających | B9: 0 | C9: 4 | D9: =B9+C9*Wyjaśnienia!$B$18/60 -> 10 | E9: =D9*Wyjaśnienia!$B$17 -> 2200 | F9: Oznaczanie zastrzeżeń prawnych robi Akademia przy czytaniu (regulamin § 8 ust. 3a), bo skaluje się razem z naborem. Organizator rozstrzyga co do zgłoszeń oznaczonych oraz co do przypadków, w których otrzymał konkretny sygnał albo sam powziął wiadomość o problemie, wraz z zawiadomieniem uczestnika. Wpisane 4 minuty na zgłoszenie są uśrednieniem: przy części zgłoszeń nie ma nic do rozstrzygania, przy oznaczonych rozstrzygnięcie i korespondencja zajmują kilkadziesiąt minut. | G9: 2027
A13: Publiczne archiwum rozmów na stronie | B13: 50 | C13: 0 | D13: =B13+C13*Wyjaśnienia!$B$18/60 -> 50 | E13: =D13*Wyjaśnienia!$B$17 -> 11000 | F13: generowanie stron z kopii, nawigacja, tryb redakcji fragmentów | G13: 2027
A14: Koordynacja podcastu: goście, terminy, publikacja | B14: 72 | C14: 0 | D14: =B14+C14*Wyjaśnienia!$B$18/60 -> 72 | E14: =D14*Wyjaśnienia!$B$17 -> 15840 | G14: 2027
A15: Razem praca | D15: =SUM(D7:D14) -> 217 | E15: =SUM(E7:E14) -> 47740
A17: KOSZTY TWARDE
A18: Pozycja | B18: Cena jednostkowa | C18: Ilość | D18: Kwota | E18: Uwagi | G18: Rok kosztu
A22: Koordynator wydania i moderacji I-IV 2028 (B2B) | B22: 40000 | C22: 1 | D22: =B22*C22 -> 40000 | E22: pełne zaangażowanie I-III 2028, moderacja archiwum i obsługa zgłoszeń przy dużym napływie | G22: 2028
A23: Korekta językowa antologii | B23: 4000 | C23: 1 | D23: =B23*C23 -> 4000 | E23: korekta dziesięciu rozmów i not | G23: 2028
A24: Skład i przygotowanie do druku (DTP) | B24: 3000 | C24: 1 | D24: =B24*C24 -> 3000 | E24: szablon plus obsługa wydania | G24: 2028
A25: Krótki nakład antologii na galę (100 egz.) | B25: 4000 | C25: 1 | D25: =B25*C25 -> 4000 | E25: gwarantowany przez organizatora, niezależny od partnera wydawniczego; nakład handlowy jest po stronie partnera. Pozycja ponoszona wyłącznie wtedy, gdy wydanie księgarskie nie będzie gotowe na dzień gali - jeżeli partner dostarczy książkę na premierę, egzemplarze dla laureatów i jury pochodzą z jego nakładu. Przy 100 egzemplarzach egzemplarz obowiązkowy to 2 sztuki (Biblioteka Narodowa i Jagiellońska); powyżej 100 egzemplarzy ustawa wymaga 17 sztuk, co jest osobnym powodem, by nie przekraczać setki. ISBN dla tego druku nie jest potrzebny, bo nie trafia do sprzedaży. | G25: 2028
A26: Nadanie ISBN i egzemplarz obowiązkowy | B26: 0 | C26: 1 | D26: =B26*C26 -> 0 | E26: nadanie bezpłatne | G26: 2028
A31: Produkcja podcastu wraz z honorarium prowadzącego (24 odcinki) | B31: 0 | C31: 1 | D31: =B31*C31 -> 0 | E31: DO WYCENY - nagranie, montaż, dźwięk, wersja wideo i dystrybucja; honorarium prowadzącego nieustalone | G31: 2027
A32: Produkcja audiobooka antologii (trzy głosy) | B32: 40000 | C32: 1 | D32: =B32*C32 -> 40000 | E32: około 10 godzin gotowego nagrania; trzej lektorzy - uczestnik, sztuczna inteligencja i komentarze jury - studio, montaż dialogowy i mastering | G32: 2028
A33: Razem koszty twarde
A35: PODSUMOWANIE
A36: Praca organizatora | D36: =E15 -> 47740
A37: Koszty twarde | D37: =SUM(D19:D32) -> 91000
A38: Wynagrodzenie wykonawcy (20% od pracy) i rezerwa (10% od całości) | D38: =D36*Wyjaśnienia!$B$33+(D36+D37)*0.1 -> 23422 | E38: wynagrodzenie liczone wyłącznie od pracy własnej; koszty zewnętrzne wchodzą bez narzutu
A39: RAZEM NETTO | D39: =SUM(D36:D38) -> 162162
A40: VAT | D40: =D39*Wyjaśnienia!$B$35 -> 37297.26
A41: DO ZAPŁATY BRUTTO - ta liczba trafia na fakturę | D41: =D39+D40 -> 199459.26

Sheet Budżet Gali
A1: Budżet Gali - gala rozstrzygnięcia pierwszej edycji
A2: Finansuje: Sponsor gali. Kwoty netto, chyba że napisano inaczej.
A3: Na żółto pola do edycji. Pozostałe liczą się same albo pochodzą z zakładki Wyjaśnienia.
A5: PRACA ORGANIZATORA
A6: Pozycja | B6: Godziny | C6: Minut na zgłoszenie | D6: Razem godzin | E6: Kwota | F6: Uwagi | G6: Rok kosztu
A7: Gala: organizacja, zdjęcia, wysyłki | B7: 45 | C7: 0 | D7: =B7+C7*Wyjaśnienia!$B$18/60 -> 45 | E7: =D7*Wyjaśnienia!$B$17 -> 9900 | F7: z koordynatorem po stronie B jest mniej | G7: 2028
A8: Razem praca | D8: =SUM(D7:D7) -> 45 | E8: =SUM(E7:E7) -> 9900
A10: KOSZTY TWARDE
A11: Pozycja | B11: Cena jednostkowa | C11: Ilość | D11: Kwota | E11: Uwagi | G11: Rok kosztu
A12: Gala: sala, obsługa, poczęstunek | B12: 8000 | C12: 1 | D12: =B12*C12 -> 8000 | E12: do negocjacji z patronem instytucjonalnym | G12: 2028
A13: Fotograf na gali | B13: 1500 | C13: 1 | D13: =B13*C13 -> 1500 | E13: zdjęcie grupowe i dokumentacja | G13: 2028
A14: Przejazdy i noclegi jury | B14: 4000 | C14: 1 | D14: =B14*C14 -> 4000 | E14: zwrot kosztów | G14: 2028
A15: Przejazdy i noclegi finalistów czterech plebiscytów na galę | B15: 32000 | C15: 1 | D15: =B15*C15 -> 32000 | E15: czterdziestu finalistów, po dziesięciu z każdego plebiscytu; przejazd i nocleg | G15: 2028
A16: Oprawa artystyczna gali | B16: 0 | C16: 1 | D16: =B16*C16 -> 0 | E16: technika, nagłośnienie, światło, honoraria za występ - do wyceny po wyborze miejsca | G16: 2028
A17: Rejestracja wideo i udostępnienie zapisu | B17: 0 | C17: 1 | D17: =B17*C17 -> 0 | E17: zapis udostępniany bezpłatnie - do wyceny | G17: 2028
A18: Prowadzenie gali | B18: 0 | C18: 1 | D18: =B18*C18 -> 0 | E18: do wyceny | G18: 2028
A19: Tantiemy dla organizacji zbiorowego zarządzania | B19: 0 | C19: 1 | D19: =B19*C19 -> 0 | E19: DO WYCENY - publiczne wykonanie muzyki na gali: hymn i trzy piosenki na żywo oraz muzyka w zwiastunach piątki filmów; obowiązek po stronie Organizatora, nieprzenoszony na uczestników (§ 12 ust. 2a regulaminu filmu) | G19: 2028
A20: Razem koszty twarde | D20: =SUM(D12:D19) -> 45500
A22: PODSUMOWANIE
A23: Praca organizatora | D23: =E8 -> 9900
A24: Koszty twarde | D24: =D20 -> 45500
A25: Rezerwa (od pracy i kosztów) | D25: =(D23+D24)*Wyjaśnienia!$B$32 -> 6648
A26: RAZEM NETTO | D26: =SUM(D23:D25) -> 62048
A27: VAT | D27: =D26*Wyjaśnienia!$B$35 -> 14271.04
A28: DO ZAPŁATY BRUTTO - ta liczba trafia na fakturę | D28: =D26+D27 -> 76319.04

Sheet Budżet Uruchomienia
A1: Budżet Uruchomienia - fundacja, znak towarowy, strona i narzędzia
A2: Finansuje: Mecenas Założycielski. Kwoty netto, chyba że napisano inaczej.
A3: Pozycje wspólne całego przedsięwzięcia, wydzielone z Budżetu Antologii 30.10.2026. Służą czterem plebiscytom, akademii, gali i wystawie, a powstają raz i działają w kolejnych edycjach. Wydzielenie bierze się stąd, że obciążanie nimi jednego partnera czyniło jego ofertę nie do obrony.
A5: PRACA ORGANIZATORA
A6: Pozycja | B6: Godziny | D6: Razem godzin | E6: Kwota | F6: Uwagi | G6: Rok kosztu
A7: Skraper i kopia archiwalna zgłoszenia | B7: 50 | D7: =B7 -> 50 | E7: =D7*Wyjaśnienia!$B$17 -> 11000 | G7: 2027
A8: Narzędzie do oceny formalnej | B8: 25 | D8: =B8 -> 25 | E8: =D8*Wyjaśnienia!$B$17 -> 5500 | G8: 2027
A9: Panel oceny dla Akademii i jury | B9: 160 | D9: =B9 -> 160 | E9: =D9*Wyjaśnienia!$B$17 -> 35200 | G9: 2027
A10: Instalowalna wersja mobilna strony: powiadomienia i tryb bez sieci | B10: 120 | D10: =B10 -> 120 | E10: =D10*Wyjaśnienia!$B$17 -> 26400 | F10: ta sama strona dodana do ekranu telefonu: manifest i instalacja, działanie bez sieci, pobranie audiobooka i e-booka do czytania oraz słuchania offline, powiadomienia o nowych zgłoszeniach wraz z obsługą subskrypcji po stronie serwera, testy na Androidzie i iPhonie | G10: 2027
A11: Razem praca | D11: =SUM(D7:D10) -> 355 | E11: =SUM(E7:E10) -> 78100
A13: KOSZTY TWARDE
A14: Pozycja | B14: Cena jednostkowa | C14: Ilość | D14: Kwota | E14: Uwagi | G14: Rok kosztu
A15: Powołanie fundacji-organizatora | B15: 3000 | C15: 1 | D15: =B15*C15 -> 3000 | E15: około 1 000 zł opłat za usługi (taksa notarialna z wypisami, wpis do rejestru stowarzyszeń i do rejestru przedsiębiorców, ogłoszenie w MSiG) oraz 2 000 zł funduszu założycielskiego, z czego 1 000 zł na działalność gospodarczą (art. 5 ust. 5 ustawy o fundacjach); fundusz nie jest kosztem usługi, tylko majątkiem wnoszonym do fundacji | G15: 2027
A16: Konsultacja prawna przed otwarciem naboru | B16: 6000 | C16: 1 | D16: =B16*C16 -> 6000 | E16: sześć obszarów, w tym licencja i archiwum; obowiązkowa przed naborem | G16: 2027
A17: Domeny, poczta, hosting, magazyn kopii archiwalnych | B17: 10000 | C17: 1 | D17: =B17*C17 -> 10000 | E17: magazyn obiektowy w UE z kopią zapasową, retencja min. 5 lat, PDF/HTML/zrzuty/EPUB; w tym skrzynka pocztowa w domenie wraz z aliasami (kontakt@, imienny) - rzędu 150-450 zł rocznie, aliasy bez dopłaty; przejście na własną skrzynkę przenosi MX i wyłącza Cloudflare Email Routing | G17: 2027
A18: Przebudowa strony: UI/UX i teksty (agencja) | B18: 15000 | C18: 1 | D18: =B18*C18 -> 15000 | E18: projekt i wdrożenie strony Nagrody wraz z copywritingiem | G18: 2027
A19: Obsługa fundacji za pierwszy rok | B19: 6000 | C19: 1 | D19: =B19*C19 -> 6000 | E19: księgowość, sprawozdanie finansowe i sprawozdanie dla ministra nadzorującego | G19: 2027
A20: Narzędzia AI i licencje oprogramowania (rok) | B20: 30000 | C20: 1 | D20: =B20*C20 -> 30000 | E20: Dostęp do narzędzi AI, bez których 1469 godzin pracy organizatora nie jest wykonalne; rzędu 2,5 tys. zł miesięcznie | G20: 2027
A21: Rejestracja znaku towarowego Konstela w EUIPO | B21: 4500 | C21: 1 | D21: =B21*C21 -> 4500 | G21: 2027
A22: Razem koszty twarde | D22: =SUM(D15:D21) -> 74500
A24: PODSUMOWANIE
A25: Praca organizatora | D25: =E11 -> 78100
A26: Koszty twarde | D26: =D22 -> 74500
A27: Wynagrodzenie wykonawcy (20% od pracy) i rezerwa (10% od całości) | D27: =D25*Wyjaśnienia!$B$33+(D25+D26)*0.1 -> 30880 | E27: wynagrodzenie liczone wyłącznie od pracy własnej; koszty zewnętrzne wchodzą bez narzutu
A28: RAZEM NETTO | D28: =SUM(D25:D27) -> 183480
A29: VAT | D29: =D28*Wyjaśnienia!$B$35 -> 42200.4
A30: DO ZAPŁATY BRUTTO - ta liczba trafia na fakturę | D30: =D28+D29 -> 225680.4
